Workbook
Name Slicer_Age: #N/A
Name Slicer_Category: #N/A
Name Slicer_Customer_ID: #N/A
Name Slicer_Gender: #N/A
Name Slicer_New_Loyalty: #N/A
Name Slicer_Region: #N/A
Name Slicer_Sales_ID: #N/A
Name Slicer_Store_Type: #N/A
Name Timeline_Order_Date__Delimited1: #N/A

Sheet Customer_Dim
A1: Customer_ID | B1: Name | C1: Age | D1: Gender | E1: City | F1: State | G1: Country | H1: Loyalty_Level
A2: CUST1000 | B2: sheena bonilla | C2: 55 | D2: Male | E2: Donaldton | F2: North Carolina | G2: USA
A3: CUST1001 | B3: Eugene Nelson | C3: 26 | D3: Female | E3: Phillipsmouth | F3: North Dakota | G3: USA | H3: Platinum
A4: CUST1002 | B4: dr. Benjamin Price | C4: 29 | D4: Female | E4: Kylebury | F4: Alabama | G4: USA | H4: Platinum
A5: CUST1003 | B5: jeremy harris | C5: 59 | D5: Female | E5: Thomastown | F5: Ohio | G5: USA | H5: Bronze
A6: CUST1004 | B6: Caroline Collins | C6: 64 | D6: Female | E6: Nicholasshire | F6: California | G6: USA | H6: Silver
A7: CUST1005 | B7: Christine Vaughn | C7: 24 | D7: Male | E7: East Amandamouth | F7: Oregon | G7: USA | H7: Bronze
A8: CUST1006 | B8: Amber Jackson | C8: 29 | D8: Female | E8: Deborahborough | F8: South Dakota | G8: USA | H8: Platinum
A9: CUST1007 | B9: Daniel Boyd | C9: 29 | D9: Female | E9: West Pamelafurt | F9: West Virginia | G9: USA | H9: Bronze
A10: CUST1008 | B10: Melissa Howard | C10: 53 | D10: Female | E10: Maynardton | F10: New Hampshire | G10: USA | H10: Gold
A11: CUST1009 | B11: Ms. Maria Leach | C11: 64 | D11: Male | E11: Melissashire | F11: Pennsylvania | G11: USA | H11: Platinum
A12: CUST1010 | B12: Dominic Page | C12: 53 | D12: Male | E12: Port Michaelburgh | F12: Pennsylvania | G12: USA | H12: Bronze
A13: CUST1011 | B13: Brian Lopez | C13: 28 | D13: Female | E13: East Krista | F13: New York | G13: USA | H13: Gold
A14: CUST1012 | B14: Kenneth Lambert | C14: 55 | D14: Female | E14: North Kathryn | F14: Kansas | G14: USA | H14: Platinum
... A19: CUST1017 | B19: Adam Cruz | C19: 60 | D19: Female | E19: Brandonville | F19: Georgia | G19: USA | H19: Platinum
A20: CUST1018 | B20: Rhonda Moss | C20: 43 | D20: Male | E20: South William | F20: Kansas | G20: USA
A21: CUST1019 | B21: Michael Torres | C21: 46 | D21: Female | E21: Gonzalezfort | F21: New Jersey | G21: USA | H21: Platinum
A22: CUST1020 | B22: Bridget Allen | C22: 59 | D22: Male | E22: Lake Shaneburgh | F22: Delaware | G22: USA | H22: Silver
A23: CUST1021 | B23: Jeff Martinez | C23: 36 | D23: Female | E23: Smithburgh | F23: Oklahoma | G23: USA | H23: Gold
A24: CUST1022 | B24: paul fox | C24: 33 | D24: Female | E24: Michaelton | F24: Hawaii | G24: USA | H24: Silver
A25: CUST1023 | B25: Jonathan Steele | C25: 52 | D25: Female | E25: Molinabury | F25: Oregon | G25: USA | H25: Silver
A26: CUST1024 | B26: Heather Collins | C26: 40 | D26: Male | E26: Rogerschester | F26: Idaho | G26: USA | H26: Platinum
A27: CUST1025 | B27: Diana Taylor | C27: 59 | D27: Female | E27: Vasqueztown | F27: California | G27: USA | H27: Bronze
A28: CUST1026 | B28: Amber Carlson | C28: 18 | D28: Female | E28: East Michellemouth | F28: Missouri | G28: USA | H28: Gold
A29: CUST1027 | B29: Leslie Johnson | C29: 31 | D29: Male | E29: Mollyshire | F29: Utah | G29: USA
A30: CUST1028 | B30: Joshua Ryan | C30: 27 | D30: Female | E30: New David | F30: New Jersey | G30: USA | H30: Platinum
A31: CUST1029 | B31: David Arnold | C31: 54 | D31: Female | E31: East Jennifer | F31: California | G31: USA | H31: Silver
A32: CUST1030 | B32: Jessica Acevedo | C32: 64 | D32: Female | E32: Amybury | F32: Pennsylvania | G32: USA | H32: Bronze
A33: CUST1031 | B33: Sarah Vance | C33: 41 | D33: Male | E33: Johnsonville | F33: Oregon | G33: USA | H33: Silver
A34: CUST1032 | B34: Mike Jennings | C34: 48 | D34: Female | E34: Fostermouth | F34: Arizona | G34: USA | H34: Gold
A35: CUST1033 | B35: Robert Jones DDS | C35: 25 | D35: Male | E35: Tristanton | F35: Oklahoma | G35: USA | H35: Platinum
A36: CUST1034 | B36: Christopher Olson | C36: 27 | D36: Female | E36: West Richard | F36: Maryland | G36: USA | H36: Platinum
A37: CUST1035 | B37: Rachel Myers | C37: 52 | D37: Male | E37: Robertberg | F37: North Dakota | G37: USA | H37: Silver
A38: CUST1036 | B38: Thomas Phillips | C38: 20 | D38: Female | E38: Luisfurt | F38: Georgia | G38: USA | H38: Gold
A39: CUST1037 | B39: Christopher Carter | C39: 27 | D39: Female | E39: Brendastad | F39: South Dakota | G39: USA
A40: CUST1038 | B40: Deanna Simpson | C40: 35 | D40: Female | E40: Brownport | F40: North Dakota | G40: USA | H40: Bronze
A41: CUST1039 | B41: Tonya Reynolds | C41: 55 | D41: Female | E41: Darleneton | F41: Michigan | G41: USA | H41: Gold
A42: CUST1040 | B42: Eric Vega | C42: 50 | D42: Male | E42: Williamsonland | F42: Kansas | G42: USA | H42: Gold
A43: CUST1041 | B43: James Gibbs | C43: 21 | D43: Male | E43: Mooneyshire | F43: Alaska | G43: USA | H43: Platinum
A44: CUST1042 | B44: William Martin | C44: 19 | D44: Male | E44: Ryanburgh | F44: Connecticut | G44: USA | H44: Platinum
...

Sheet Cleaned Customer Dim
A1: Customer_ID | B1: Name | C1: Proper Name | D1: Age | E1: Gender | F1: City | G1: State | H1: Country | I1: Loyalty_Level | J1: New Loyalty
A2: CUST1000 | B2: Sheena Bonilla | C2: =PROPER($B$2:$B$501) -> Sheena Bonilla | D2: 55 | E2: Male | F2: Donaldton | G2: North Carolina | H2: USA | J2: =IF(I2="","Platinum",I2) -> Platinum | M2: Sum of Age | N2: Column Labels | T2: Age | U2: 55
A3: CUST1001 | B3: Eugene Nelson | C3: =PROPER($B$2:$B$501) -> Eugene Nelson | D3: 26 | E3: Female | F3: Phillipsmouth | G3: North Dakota | H3: USA | I3: Platinum | J3: =IF(I3="","Platinum",I3) -> Platinum | M3: Row Labels | N3: Female | O3: Male
A4: CUST1002 | B4: dr. Benjamin Price | C4: =PROPER($B$2:$B$501) -> Dr. Benjamin Price | D4: 29 | E4: Female | F4: Kylebury | G4: Alabama | H4: USA | I4: Platinum | J4: =IF(I4="","Platinum",I4) -> Platinum | M4: Bronze | N4: 2490 | O4: 2647 | T4: Count of Gender | U4: Column Labels
A5: CUST1003 | B5: jeremy harris | C5: =PROPER($B$2:$B$501) -> Jeremy Harris | D5: 59 | E5: Female | F5: Thomastown | G5: Ohio | H5: USA | I5: Bronze | J5: =IF(I5="","Platinum",I5) -> Bronze | M5: Gold | N5: 2849 | O5: 2107 | T5: Row Labels | U5: Bronze | V5: Gold | W5: Platinum | X5: Silver | Y5: Grand Total
A6: CUST1004 | B6: Caroline Collins | C6: =PROPER($B$2:$B$501) -> Caroline Collins | D6: 64 | E6: Female | F6: Nicholasshire | G6: California | H6: USA | I6: Silver | J6: =IF(I6="","Platinum",I6) -> Silver | M6: Platinum | N6: 3542 | O6: 2879 | T6: USA | U6: 1 | V6: 2 | W6: 5 | X6: 1 | Y6: 9
A7: CUST1005 | B7: Christine Vaughn | C7: =PROPER($B$2:$B$501) -> Christine Vaughn | D7: 24 | E7: Male | F7: East Amandamouth | G7: Oregon | H7: USA | I7: Bronze | J7: =IF(I7="","Platinum",I7) -> Bronze | M7: Silver | N7: 2060 | O7: 2207 | T7: Grand Total | U7: 1 | V7: 2 | W7: 5 | X7: 1 | Y7: 9
A8: CUST1006 | B8: Amber Jackson | C8: =PROPER($B$2:$B$501) -> Amber Jackson | D8: 29 | E8: Female | F8: Deborahborough | G8: South Dakota | H8: USA | I8: Platinum | J8: =IF(I8="","Platinum",I8) -> Platinum | M8: Grand Total | N8: 10941 | O8: 9840
A9: CUST1007 | B9: Daniel Boyd | C9: =PROPER($B$2:$B$501) -> Daniel Boyd | D9: 29 | E9: Female | F9: West Pamelafurt | G9: West Virginia | H9: USA | I9: Bronze | J9: =IF(I9="","Platinum",I9) -> Bronze
A10: CUST1008 | B10: Melissa Howard | C10: =PROPER($B$2:$B$501) -> Melissa Howard | D10: 53 | E10: Female | F10: Maynardton | G10: New Hampshire | H10: USA | I10: Gold | J10: =IF(I10="","Platinum",I10) -> Gold
A11: CUST1009 | B11: Ms. Maria Leach | C11: =PROPER($B$2:$B$501) -> Ms. Maria Leach | D11: 64 | E11: Male | F11: Melissashire | G11: Pennsylvania | H11: USA | I11: Platinum | J11: =IF(I11="","Platinum",I11) -> Platinum | M11: Count of Country | N11: Column Labels
A12: CUST1010 | B12: Dominic Page | C12: =PROPER($B$2:$B$501) -> Dominic Page | D12: 53 | E12: Male | F12: Port Michaelburgh | G12: Pennsylvania | H12: USA | I12: Bronze | J12: =IF(I12="","Platinum",I12) -> Bronze | M12: Row Labels | N12: Bronze | O12: Gold | P12: Platinum | Q12: Silver | R12: Grand Total
A13: CUST1011 | B13: Brian Lopez | C13: =PROPER($B$2:$B$501) -> Brian Lopez | D13: 28 | E13: Female | F13: East Krista | G13: New York | H13: USA | I13: Gold | J13: =IF(I13="","Platinum",I13) -> Gold | M13: Female | N13: 60 | O13: 68 | P13: 83 | Q13: 51 | R13: 262
A14: CUST1012 | B14: Kenneth Lambert | C14: =PROPER($B$2:$B$501) -> Kenneth Lambert | D14: 55 | E14: Female | F14: North Kathryn | G14: Kansas | H14: USA | I14: Platinum | J14: =IF(I14="","Platinum",I14) -> Platinum | M14: Male | N14: 65 | O14: 54 | P14: 66 | Q14: 53 | R14: 238
A15: CUST1013 | B15: Nathan Hernandez | C15: =PROPER($B$2:$B$501) -> Nathan Hernandez | D15: 32 | E15: Female | F15: New Becky | G15: Montana | H15: USA | I15: Silver | J15: =IF(I15="","Platinum",I15) -> Silver | M15: Grand Total | N15: 125 | O15: 122 | P15: 149 | Q15: 104 | R15: 500
A16: CUST1014 | B16: Ashley Cohen | C16: =PROPER($B$2:$B$501) -> Ashley Cohen | D16: 53 | E16: Female | F16: Lake Kristamouth | G16: Nebraska | H16: USA | I16: Silver | J16: =IF(I16="","Platinum",I16) -> Silver
A17: CUST1015 | B17: Laura Alvarez | C17: =PROPER($B$2:$B$501) -> Laura Alvarez | D17: 49 | E17: Female | F17: Lawsonhaven | G17: Washington | H17: USA | I17: Platinum | J17: =IF(I17="","Platinum",I17) -> Platinum | M17: Count of State | N17: Column Labels
A18: CUST1016 | B18: John Scott | C18: =PROPER($B$2:$B$501) -> John Scott | D18: 24 | E18: Female | F18: South Christopher | G18: Pennsylvania | H18: USA | I18: Bronze | J18: =IF(I18="","Platinum",I18) -> Bronze | N18: United States of America | O18: USA | Q18: Grand Total
A19: CUST1017 | B19: Adam Cruz | C19: =PROPER($B$2:$B$501) -> Adam Cruz | D19: 60 | E19: Female | F19: Brandonville | G19: Georgia | H19: USA | I19: Platinum | J19: =IF(I19="","Platinum",I19) -> Platinum | M19: Row Labels | N19: Male | O19: Female | P19: Male
A20: CUST1018 | B20: Rhonda Moss | C20: =PROPER($B$2:$B$501) -> Rhonda Moss | D20: 43 | E20: Male | F20: South William | G20: Kansas | H20: USA | J20: =IF(I20="","Platinum",I20) -> Platinum | M20: Bronze | N20: 1 | O20: 60 | P20: 64 | Q20: 125
A21: CUST1019 | B21: Michael Torres | C21: =PROPER($B$2:$B$501) -> Michael Torres | D21: 46 | E21: Female | F21: Gonzalezfort | G21: New Jersey | H21: USA | I21: Platinum | J21: =IF(I21="","Platinum",I21) -> Platinum | M21: Gold | O21: 68 | P21: 54 | Q21: 122
A22: CUST1020 | B22: Bridget Allen | C22: =PROPER($B$2:$B$501) -> Bridget Allen | D22: 59 | E22: Male | F22: Lake Shaneburgh | G22: Delaware | H22: USA | I22: Silver | J22: =IF(I22="","Platinum",I22) -> Silver | M22: Platinum | N22: 1 | O22: 83 | P22: 65 | Q22: 149
A23: CUST1021 | B23: Jeff Martinez | C23: =PROPER($B$2:$B$501) -> Jeff Martinez | D23: 36 | E23: Female | F23: Smithburgh | G23: Oklahoma | H23: USA | I23: Gold | J23: =IF(I23="","Platinum",I23) -> Gold | M23: Silver | N23: 1 | O23: 51 | P23: 52 | Q23: 104
A24: CUST1022 | B24: Paul Fox | C24: =PROPER($B$2:$B$501) -> Paul Fox | D24: 33 | E24: Female | F24: Michaelton | G24: Hawaii | H24: USA | I24: Silver | J24: =IF(I24="","Platinum",I24) -> Silver | M24: Grand Total | N24: 3 | O24: 262 | P24: 235 | Q24: 500
A25: CUST1023 | B25: Jonathan Steele | C25: =PROPER($B$2:$B$501) -> Jonathan Steele | D25: 52 | E25: Female | F25: Molinabury | G25: Oregon | H25: USA | I25: Silver | J25: =IF(I25="","Platinum",I25) -> Silver
A26: CUST1024 | B26: Heather Collins | C26: =PROPER($B$2:$B$501) -> Heather Collins | D26: 40 | E26: Male | F26: Rogerschester | G26: Idaho | H26: USA | I26: Platinum | J26: =IF(I26="","Platinum",I26) -> Platinum
A27: CUST1025 | B27: Diana Taylor | C27: =PROPER($B$2:$B$501) -> Diana Taylor | D27: 59 | E27: Female | F27: Vasqueztown | G27: California | H27: USA | I27: Bronze | J27: =IF(I27="","Platinum",I27) -> Bronze
A28: CUST1026 | B28: Amber Carlson | C28: =PROPER($B$2:$B$501) -> Amber Carlson | D28: 18 | E28: Female | F28: East Michellemouth | G28: Missouri | H28: USA | I28: Gold | J28: =IF(I28="","Platinum",I28) -> Gold
A29: CUST1027 | B29: Leslie Johnson | C29: =PROPER($B$2:$B$501) -> Leslie Johnson | D29: 31 | E29: Male | F29: Mollyshire | G29: Utah | H29: USA | J29: =IF(I29="","Platinum",I29) -> Platinum
A30: CUST1028 | B30: Joshua Ryan | C30: =PROPER($B$2:$B$501) -> Joshua Ryan | D30: 27 | E30: Female | F30: New David | G30: New Jersey | H30: USA | I30: Platinum | J30: =IF(I30="","Platinum",I30) -> Platinum
A31: CUST1029 | B31: David Arnold | C31: =PROPER($B$2:$B$501) -> David Arnold | D31: 54 | E31: Female | F31: East Jennifer | G31: California | H31: USA | I31: Silver | J31: =IF(I31="","Platinum",I31) -> Silver
A32: CUST1030 | B32: Jessica Acevedo | C32: =PROPER($B$2:$B$501) -> Jessica Acevedo | D32: 64 | E32: Female | F32: Amybury | G32: Pennsylvania | H32: USA | I32: Bronze | J32: =IF(I32="","Platinum",I32) -> Bronze
A33: CUST1031 | B33: Sarah Vance | C33: =PROPER($B$2:$B$501) -> Sarah Vance | D33: 41 | E33: Male | F33: Johnsonville | G33: Oregon | H33: USA | I33: Silver | J33: =IF(I33="","Platinum",I33) -> Silver
A34: CUST1032 | B34: Mike Jennings | C34: =PROPER($B$2:$B$501) -> Mike Jennings | D34: 48 | E34: Female | F34: Fostermouth | G34: Arizona | H34: USA | I34: Gold | J34: =IF(I34="","Platinum",I34) -> Gold
A35: CUST1033 | B35: Robert Jones DDS | C35: =PROPER($B$2:$B$501) -> Robert Jones Dds | D35: 25 | E35: Male | F35: Tristanton | G35: Oklahoma | H35: USA | I35: Platinum | J35: =IF(I35="","Platinum",I35) -> Platinum
A36: CUST1034 | B36: Christopher Olson | C36: =PROPER($B$2:$B$501) -> Christopher Olson | D36: 27 | E36: Female | F36: West Richard | G36: Maryland | H36: USA | I36: Platinum | J36: =IF(I36="","Platinum",I36) -> Platinum
A37: CUST1035 | B37: Rachel Myers | C37: =PROPER($B$2:$B$501) -> Rachel Myers | D37: 52 | E37: Male | F37: Robertberg | G37: North Dakota | H37: USA | I37: Silver | J37: =IF(I37="","Platinum",I37) -> Silver
A38: CUST1036 | B38: Thomas Phillips | C38: =PROPER($B$2:$B$501) -> Thomas Phillips | D38: 20 | E38: Female | F38: Luisfurt | G38: Georgia | H38: USA | I38: Gold | J38: =IF(I38="","Platinum",I38) -> Gold
A39: CUST1037 | B39: Christopher Carter | C39: =PROPER($B$2:$B$501) -> Christopher Carter | D39: 27 | E39: Female | F39: Brendastad | G39: South Dakota | H39: USA | J39: =IF(I39="","Platinum",I39) -> Platinum
A40: CUST1038 | B40: Deanna Simpson | C40: =PROPER($B$2:$B$501) -> Deanna Simpson | D40: 35 | E40: Female | F40: Brownport | G40: North Dakota | H40: USA | I40: Bronze | J40: =IF(I40="","Platinum",I40) -> Bronze
...

Sheet Product_Dim
A1: Product_ID | B1: Product_Name | C1: Category | D1: Sub_Category | E1: Brand | F1: Cost | G1: Stock
A2: PROD0 | B2: Brother Laser Printer | C2: Electronics | D2: Computer | E2: Hunt Inc | F2: 112.42 | G2: 416
A3: PROD1 | B3: Men's Graphic T-Shirt | C3: Clothing | D3: Tops | E3: Terry-Moore | F3: 342.56 | G3: 181
A4: PROD2 | B4: Women's Casual Hoodie | C4: Clothing | D4: Outerwear | E4: Sims Inc | G4: 352
A5: P-3 | B5: Men's Running Jacket | C5: Clothing | D5: Outerwear | E5: Pineda Ltd | F5: 364.67 | G5: 452
A6: PROD4 | B6: Women's Yoga Pants | C6: Clothing | D6: Bottoms | E6: Gonzales-Davis | F6: 306.46 | G6: 487
A7: PROD5 | B7: Men's Leather Belt | C7: Clothing | D7: Accessories | E7: Baldwin, Garza and Gonzalez | F7: 261 | G7: 59
A8: PROD6 | B8: Herbal Face Moisturizer | C8: Beauty | D8: Skincare | E8: Davidson PLC | F8: 312.8 | G8: 350
A9: PROD7 | B9: LED Table Lamp | C9: Home | D9: Lighting | E9: Harrell LLC | F9: 218.86 | G9: 170
A10: PROD8 | B10: Wireless Bluetooth Earbuds | C10: Electronics | D10: Audio | E10: Perez-Johnston | F10: 439.07 | G10: 142
A11: PROD9 | B11: Adjustable Dumbbell Set | C11: Sports | D11: Fitness | E11: Hill PLC | F11: 495.72 | G11: 323
A12: PROD10 | B12: Ceramic Kitchen Bowl Set | C12: Home | D12: Kitchen | E12: Hamilton Group | F12: 298.86 | G12: 308
A13: PROD11 | B13: HD Smart TV Stick | C13: Electronics | D13: Accessories | E13: Gibson, Hobbs and Weaver | F13: 449.4
A14: PROD12 | B14: Hair Strengthening Shampoo | C14: Beauty | D14: Haircare | E14: Rice LLC | F14: 115.82 | G14: 460
A15: PROD13 | B15: USB-C Fast Charger | C15: Electronics | D15: Accessories | E15: Dawson-Perkins | F15: 242.23 | G15: 453
A16: PROD14 | B16: Decorative Wall Mirror | C16: Home | D16: Decor | E16: Luna, Anderson and Bowman | F16: 48.01 | G16: 439
A17: PROD15 | B17: 4K Home Projector | C17: Electronics | D17: Appliances | E17: Thomas LLC | F17: 465.34 | G17: 301
A18: P-16 | B18: Beard Grooming Kit | C18: Beauty | D18: Grooming | E18: Erickson-Green | F18: 337.42 | G18: 256
A19: PROD17 | B19: Soccer Training Cone Set | C19: Sports | D19: Accessories | E19: Ford, Murphy and Wilson | F19: 144.53 | G19: 367
A20: PROD18 | B20: Women's Denim Jeans | C20: Clothing | D20: Bottoms | E20: Guerra-Hendrix | G20: 343
A21: PROD19 | B21: Knee Support Brace | C21: Sports | D21: Equipment | E21: May-Reese | F21: 21.34 | G21: 65
A22: PROD20 | B22: Outdoor Sports Water Bottle | C22: Sports | D22: Accessories | E22: Soto-Ellis | F22: 131.51
A23: PROD21 | B23: Multi-Purpose Storage Box | C23: Home | D23: Storage | E23: Gardner-Montes | F23: 123.46 | G23: 76
A24: PROD22 | B24: Carbon Fiber Tennis Racket | C24: Sports | D24: Equipment | E24: Flores, Pineda and Rodriguez | F24: 484.62 | G24: 432
A25: PROD23 | B25: Men's Formal Shirt | C25: Clothing | D25: Tops | E25: Moon, Mora and Santos | G25: 360
A26: PROD24 | B26: Foldable Camping Chair | C26: Sports | D26: Outdoor | E26: Cook Ltd | F26: 166.06 | G26: 340
A27: PROD25 | B27: Women's Scarf Set | C27: Clothing | D27: Accessories | E27: Brown and Sons | F27: 174.02 | G27: 268
A28: PROD26 | B28: Wireless Bluetooth Speaker | C28: Electronics | D28: Audio | E28: Reed-Schmidt | F28: 322.41 | G28: 213
A29: PROD27 | B29: Decorative Floor Vase | C29: Home | D29: Decor | E29: Khan, Jones and Paul | G29: 378
A30: PROD28 | B30: Sports Stopwatch Timer | C30: Sports | D30: Accessories | E30: Burns-Hansen | F30: 38.76 | G30: 137
A31: PROD29 | B31: Fabric Sofa Throw Blanket | C31: Home | D31: Decor | E31: Hoffman Group | F31: 218.48 | G31: 276
A32: PROD30 | B32: Stainless Steel Cutlery Set | C32: Home | D32: Kitchen | E32: Stevens, Fernandez and Martin | F32: 19.52 | G32: 57
A33: PROD31 | B33: Basketball | C33: Sports | D33: Team Sports | E33: Nolan-Snow | F33: 204.39 | G33: 281
A34: PROD32 | B34: Vitamin C Face Serum | C34: Beauty | D34: Skincare | E34: Griffin Ltd | F34: 283.83 | G34: 244
A35: PROD33 | B35: Modern Wall Clock | C35: Home | D35: Decor | E35: Weiss-Watson | F35: 179.77 | G35: 305
A36: PROD34 | B36: Gaming Mechanical Keyboard | C36: Electronics | D36: Computer | E36: Lucero LLC | F36: 419.28 | G36: 86
A37: PROD35 | B37: Bedroom Table Lamp | C37: Home | D37: Lighting | E37: Jones LLC | F37: 382.22 | G37: 329
A38: PROD36 | B38: Women's Summer Dress | C38: Clothing | D38: Tops | E38: Smith-Mills | F38: 223.43 | G38: 154
A39: PROD37 | B39: Men's Casual Sneakers | C39: Clothing | D39: Footwear | E39: Hogan-Lee | F39: 353.47 | G39: 214
A40: PROD38 | B40: Sports Water Hydration Pack | C40: Sports | D40: Outdoor | E40: Sims-Smith | F40: 135.61 | G40: 394
...

Sheet Cleaned Product Dim
A1: Product_ID | B1: Product_Name | C1: Category | D1: Brand | E1: Cost | F1: Stock | G1: New Cost | H1: New Stock
A2: PROD0 | B2: Brother Laser Printer | C2: Electronics | D2: Hunt Inc | E2: 112.42 | F2: 416 | G2: =IF(E2="",AVERAGEIF(($C$2:$C$101),C2,($E$2:$E$101)),E2) -> 112.42 | H2: =IF(F2="",AVERAGEIF(($C$2:$C$101),C2,($F$2:$F$101)),F2) -> 416 | K2: New Cost | M2: New Stock
A3: PROD1 | B3: Men's Graphic T-Shirt | C3: Clothing | D3: Terry-Moore | E3: 342.56 | F3: 181 | G3: =IF(E3="",AVERAGEIF(($C$2:$C$101),C3,($E$2:$E$101)),E3) -> 342.56 | H3: =IF(F3="",AVERAGEIF(($C$2:$C$101),C3,($F$2:$F$101)),F3) -> 181
A4: PROD2 | B4: Women's Casual Hoodie | C4: Clothing | D4: Sims Inc | F4: 352 | G4: =IF(E4="",AVERAGEIF(($C$2:$C$101),C4,($E$2:$E$101)),E4) -> 265.73267 | H4: =IF(F4="",AVERAGEIF(($C$2:$C$101),C4,($F$2:$F$101)),F4) -> 352 | K4: Mean | L4: 254.12936 | M4: Mean | N4: 273.11708
A5: PROD3 | B5: Men's Running Jacket | C5: Clothing | D5: Pineda Ltd | E5: 364.67 | F5: 452 | G5: =IF(E5="",AVERAGEIF(($C$2:$C$101),C5,($E$2:$E$101)),E5) -> 364.67 | H5: =IF(F5="",AVERAGEIF(($C$2:$C$101),C5,($F$2:$F$101)),F5) -> 452 | K5: Standard Error | L5: 13.085141 | M5: Standard Error | N5: 13.004017
A6: PROD4 | B6: Women's Yoga Pants | C6: Clothing | D6: Gonzales-Davis | E6: 306.46 | F6: 487 | G6: =IF(E6="",AVERAGEIF(($C$2:$C$101),C6,($E$2:$E$101)),E6) -> 306.46 | H6: =IF(F6="",AVERAGEIF(($C$2:$C$101),C6,($F$2:$F$101)),F6) -> 487 | K6: Median | L6: 248.19808 | M6: Median | N6: 275.35
A7: PROD5 | B7: Men's Leather Belt | C7: Clothing | D7: Baldwin, Garza and Gonzalez | E7: 261 | F7: 59 | G7: =IF(E7="",AVERAGEIF(($C$2:$C$101),C7,($E$2:$E$101)),E7) -> 261 | H7: =IF(F7="",AVERAGEIF(($C$2:$C$101),C7,($F$2:$F$101)),F7) -> 59 | K7: Mode | L7: 265.73267 | M7: Mode | N7: 82
A8: PROD6 | B8: Herbal Face Moisturizer | C8: Beauty | D8: Davidson PLC | E8: 312.8 | F8: 350 | G8: =IF(E8="",AVERAGEIF(($C$2:$C$101),C8,($E$2:$E$101)),E8) -> 312.8 | H8: =IF(F8="",AVERAGEIF(($C$2:$C$101),C8,($F$2:$F$101)),F8) -> 350 | K8: Standard Deviation | L8: 130.85141 | M8: Standard Deviation | N8: 130.04017
A9: PROD7 | B9: LED Table Lamp | C9: Home | D9: Harrell LLC | E9: 218.86 | F9: 170 | G9: =IF(E9="",AVERAGEIF(($C$2:$C$101),C9,($E$2:$E$101)),E9) -> 218.86 | H9: =IF(F9="",AVERAGEIF(($C$2:$C$101),C9,($F$2:$F$101)),F9) -> 170 | K9: Sample Variance | L9: 17122.09 | M9: Sample Variance | N9: 16910.445
A10: PROD8 | B10: Wireless Bluetooth Earbuds | C10: Electronics | D10: Perez-Johnston | E10: 439.07 | F10: 142 | G10: =IF(E10="",AVERAGEIF(($C$2:$C$101),C10,($E$2:$E$101)),E10) -> 439.07 | H10: =IF(F10="",AVERAGEIF(($C$2:$C$101),C10,($F$2:$F$101)),F10) -> 142 | K10: Kurtosis | L10: -0.95127662 | M10: Kurtosis | N10: -1.158146
A11: PROD9 | B11: Adjustable Dumbbell Set | C11: Sports | D11: Hill PLC | E11: 495.72 | F11: 323 | G11: =IF(E11="",AVERAGEIF(($C$2:$C$101),C11,($E$2:$E$101)),E11) -> 495.72 | H11: =IF(F11="",AVERAGEIF(($C$2:$C$101),C11,($F$2:$F$101)),F11) -> 323 | K11: Skewness | L11: 0.050263902 | M11: Skewness | N11: 0.00071961406
A12: PROD10 | B12: Ceramic Kitchen Bowl Set | C12: Home | D12: Hamilton Group | E12: 298.86 | F12: 308 | G12: =IF(E12="",AVERAGEIF(($C$2:$C$101),C12,($E$2:$E$101)),E12) -> 298.86 | H12: =IF(F12="",AVERAGEIF(($C$2:$C$101),C12,($F$2:$F$101)),F12) -> 308 | K12: Range | L12: 478.41 | M12: Range | N12: 439
A13: PROD11 | B13: HD Smart TV Stick | C13: Electronics | D13: Gibson, Hobbs and Weaver | E13: 449.4 | G13: =IF(E13="",AVERAGEIF(($C$2:$C$101),C13,($E$2:$E$101)),E13) -> 449.4 | H13: =IF(F13="",AVERAGEIF(($C$2:$C$101),C13,($F$2:$F$101)),F13) -> 274.7 | K13: Minimum | L13: 17.31 | M13: Minimum | N13: 57
A14: PROD12 | B14: Hair Strengthening Shampoo | C14: Beauty | D14: Rice LLC | E14: 115.82 | F14: 460 | G14: =IF(E14="",AVERAGEIF(($C$2:$C$101),C14,($E$2:$E$101)),E14) -> 115.82 | H14: =IF(F14="",AVERAGEIF(($C$2:$C$101),C14,($F$2:$F$101)),F14) -> 460 | K14: Maximum | L14: 495.72 | M14: Maximum | N14: 496
A15: PROD13 | B15: USB-C Fast Charger | C15: Electronics | D15: Dawson-Perkins | E15: 242.23 | F15: 453 | G15: =IF(E15="",AVERAGEIF(($C$2:$C$101),C15,($E$2:$E$101)),E15) -> 242.23 | H15: =IF(F15="",AVERAGEIF(($C$2:$C$101),C15,($F$2:$F$101)),F15) -> 453 | K15: Sum | L15: 25412.936 | M15: Sum | N15: 27311.708
A16: PROD14 | B16: Decorative Wall Mirror | C16: Home | D16: Luna, Anderson and Bowman | E16: 48.01 | F16: 439 | G16: =IF(E16="",AVERAGEIF(($C$2:$C$101),C16,($E$2:$E$101)),E16) -> 48.01 | H16: =IF(F16="",AVERAGEIF(($C$2:$C$101),C16,($F$2:$F$101)),F16) -> 439 | K16: Count | L16: 100 | M16: Count | N16: 100
A17: PROD15 | B17: 4K Home Projector | C17: Electronics | D17: Thomas LLC | E17: 465.34 | F17: 301 | G17: =IF(E17="",AVERAGEIF(($C$2:$C$101),C17,($E$2:$E$101)),E17) -> 465.34 | H17: =IF(F17="",AVERAGEIF(($C$2:$C$101),C17,($F$2:$F$101)),F17) -> 301
A18: PROD16 | B18: Beard Grooming Kit | C18: Beauty | D18: Erickson-Green | E18: 337.42 | F18: 256 | G18: =IF(E18="",AVERAGEIF(($C$2:$C$101),C18,($E$2:$E$101)),E18) -> 337.42 | H18: =IF(F18="",AVERAGEIF(($C$2:$C$101),C18,($F$2:$F$101)),F18) -> 256
A19: PROD17 | B19: Soccer Training Cone Set | C19: Sports | D19: Ford, Murphy and Wilson | E19: 144.53 | F19: 367 | G19: =IF(E19="",AVERAGEIF(($C$2:$C$101),C19,($E$2:$E$101)),E19) -> 144.53 | H19: =IF(F19="",AVERAGEIF(($C$2:$C$101),C19,($F$2:$F$101)),F19) -> 367 | K19: PROD1
A20: PROD18 | B20: Women's Denim Jeans | C20: Clothing | D20: Guerra-Hendrix | F20: 343 | G20: =IF(E20="",AVERAGEIF(($C$2:$C$101),C20,($E$2:$E$101)),E20) -> 265.73267 | H20: =IF(F20="",AVERAGEIF(($C$2:$C$101),C20,($F$2:$F$101)),F20) -> 343 | J20: vlookup | K20: =VLOOKUP(K19,$A$2:$H$101,4,FALSE) -> Terry-Moore
A21: PROD19 | B21: Knee Support Brace | C21: Sports | D21: May-Reese | E21: 21.34 | F21: 65 | G21: =IF(E21="",AVERAGEIF(($C$2:$C$101),C21,($E$2:$E$101)),E21) -> 21.34 | H21: =IF(F21="",AVERAGEIF(($C$2:$C$101),C21,($F$2:$F$101)),F21) -> 65
A22: PROD20 | B22: Outdoor Sports Water Bottle | C22: Sports | D22: Soto-Ellis | E22: 131.51 | G22: =IF(E22="",AVERAGEIF(($C$2:$C$101),C22,($E$2:$E$101)),E22) -> 131.51 | H22: =IF(F22="",AVERAGEIF(($C$2:$C$101),C22,($F$2:$F$101)),F22) -> 281.95833 | K22: Row Labels | L22: Sum of New Cost | M22: Sum of New Stock
A23: PROD21 | B23: Multi-Purpose Storage Box | C23: Home | D23: Gardner-Montes | E23: 123.46 | F23: 76 | G23: =IF(E23="",AVERAGEIF(($C$2:$C$101),C23,($E$2:$E$101)),E23) -> 123.46 | H23: =IF(F23="",AVERAGEIF(($C$2:$C$101),C23,($F$2:$F$101)),F23) -> 76 | K23: Beauty | L23: 3756.2423 | M23: 4816
A24: PROD22 | B24: Carbon Fiber Tennis Racket | C24: Sports | D24: Flores, Pineda and Rodriguez | E24: 484.62 | F24: 432 | G24: =IF(E24="",AVERAGEIF(($C$2:$C$101),C24,($E$2:$E$101)),E24) -> 484.62 | H24: =IF(F24="",AVERAGEIF(($C$2:$C$101),C24,($F$2:$F$101)),F24) -> 432 | K24: Clothing | L24: 4783.188 | M24: 4931
A25: PROD23 | B25: Men's Formal Shirt | C25: Clothing | D25: Moon, Mora and Santos | F25: 360 | G25: =IF(E25="",AVERAGEIF(($C$2:$C$101),C25,($E$2:$E$101)),E25) -> 265.73267 | H25: =IF(F25="",AVERAGEIF(($C$2:$C$101),C25,($F$2:$F$101)),F25) -> 360 | K25: Electronics | L25: 6647.66 | M25: 5768.7
A26: PROD24 | B26: Foldable Camping Chair | C26: Sports | D26: Cook Ltd | E26: 166.06 | F26: 340 | G26: =IF(E26="",AVERAGEIF(($C$2:$C$101),C26,($E$2:$E$101)),E26) -> 166.06 | H26: =IF(F26="",AVERAGEIF(($C$2:$C$101),C26,($F$2:$F$101)),F26) -> 340 | K26: Home | L26: 4930.926 | M26: 4747.05
A27: PROD25 | B27: Women's Scarf Set | C27: Clothing | D27: Brown and Sons | E27: 174.02 | F27: 268 | G27: =IF(E27="",AVERAGEIF(($C$2:$C$101),C27,($E$2:$E$101)),E27) -> 174.02 | H27: =IF(F27="",AVERAGEIF(($C$2:$C$101),C27,($F$2:$F$101)),F27) -> 268 | K27: Sports | L27: 5294.92 | M27: 7048.9583
A28: PROD26 | B28: Wireless Bluetooth Speaker | C28: Electronics | D28: Reed-Schmidt | E28: 322.41 | F28: 213 | G28: =IF(E28="",AVERAGEIF(($C$2:$C$101),C28,($E$2:$E$101)),E28) -> 322.41 | H28: =IF(F28="",AVERAGEIF(($C$2:$C$101),C28,($F$2:$F$101)),F28) -> 213 | K28: Grand Total | L28: 25412.936 | M28: 27311.708
A29: PROD27 | B29: Decorative Floor Vase | C29: Home | D29: Khan, Jones and Paul | F29: 378 | G29: =IF(E29="",AVERAGEIF(($C$2:$C$101),C29,($E$2:$E$101)),E29) -> 234.806 | H29: =IF(F29="",AVERAGEIF(($C$2:$C$101),C29,($F$2:$F$101)),F29) -> 378
A30: PROD28 | B30: Sports Stopwatch Timer | C30: Sports | D30: Burns-Hansen | E30: 38.76 | F30: 137 | G30: =IF(E30="",AVERAGEIF(($C$2:$C$101),C30,($E$2:$E$101)),E30) -> 38.76 | H30: =IF(F30="",AVERAGEIF(($C$2:$C$101),C30,($F$2:$F$101)),F30) -> 137 | K30: Row Labels | L30: Average of New Cost
A31: PROD29 | B31: Fabric Sofa Throw Blanket | C31: Home | D31: Hoffman Group | E31: 218.48 | F31: 276 | G31: =IF(E31="",AVERAGEIF(($C$2:$C$101),C31,($E$2:$E$101)),E31) -> 218.48 | H31: =IF(F31="",AVERAGEIF(($C$2:$C$101),C31,($F$2:$F$101)),F31) -> 276 | K31: Beauty | L31: 250.41615
A32: PROD30 | B32: Stainless Steel Cutlery Set | C32: Home | D32: Stevens, Fernandez and Martin | E32: 19.52 | F32: 57 | G32: =IF(E32="",AVERAGEIF(($C$2:$C$101),C32,($E$2:$E$101)),E32) -> 19.52 | H32: =IF(F32="",AVERAGEIF(($C$2:$C$101),C32,($F$2:$F$101)),F32) -> 57 | K32: Clothing | L32: 265.73267
A33: PROD31 | B33: Basketball | C33: Sports | D33: Nolan-Snow | E33: 204.39 | F33: 281 | G33: =IF(E33="",AVERAGEIF(($C$2:$C$101),C33,($E$2:$E$101)),E33) -> 204.39 | H33: =IF(F33="",AVERAGEIF(($C$2:$C$101),C33,($F$2:$F$101)),F33) -> 281 | K33: Electronics | L33: 316.55524
A34: PROD32 | B34: Vitamin C Face Serum | C34: Beauty | D34: Griffin Ltd | E34: 283.83 | F34: 244 | G34: =IF(E34="",AVERAGEIF(($C$2:$C$101),C34,($E$2:$E$101)),E34) -> 283.83 | H34: =IF(F34="",AVERAGEIF(($C$2:$C$101),C34,($F$2:$F$101)),F34) -> 244 | K34: Home | L34: 234.806
A35: PROD33 | B35: Modern Wall Clock | C35: Home | D35: Weiss-Watson | E35: 179.77 | F35: 305 | G35: =IF(E35="",AVERAGEIF(($C$2:$C$101),C35,($E$2:$E$101)),E35) -> 179.77 | H35: =IF(F35="",AVERAGEIF(($C$2:$C$101),C35,($F$2:$F$101)),F35) -> 305 | K35: Sports | L35: 211.7968
A36: PROD34 | B36: Gaming Mechanical Keyboard | C36: Electronics | D36: Lucero LLC | E36: 419.28 | F36: 86 | G36: =IF(E36="",AVERAGEIF(($C$2:$C$101),C36,($E$2:$E$101)),E36) -> 419.28 | H36: =IF(F36="",AVERAGEIF(($C$2:$C$101),C36,($F$2:$F$101)),F36) -> 86
A37: PROD35 | B37: Bedroom Table Lamp | C37: Home | D37: Jones LLC | E37: 382.22 | F37: 329 | G37: =IF(E37="",AVERAGEIF(($C$2:$C$101),C37,($E$2:$E$101)),E37) -> 382.22 | H37: =IF(F37="",AVERAGEIF(($C$2:$C$101),C37,($F$2:$F$101)),F37) -> 329
A38: PROD36 | B38: Women's Summer Dress | C38: Clothing | D38: Smith-Mills | E38: 223.43 | F38: 154 | G38: =IF(E38="",AVERAGEIF(($C$2:$C$101),C38,($E$2:$E$101)),E38) -> 223.43 | H38: =IF(F38="",AVERAGEIF(($C$2:$C$101),C38,($F$2:$F$101)),F38) -> 154 | K38: Row Labels | L38: Max of New Stock
A39: PROD37 | B39: Men's Casual Sneakers | C39: Clothing | D39: Hogan-Lee | E39: 353.47 | F39: 214 | G39: =IF(E39="",AVERAGEIF(($C$2:$C$101),C39,($E$2:$E$101)),E39) -> 353.47 | H39: =IF(F39="",AVERAGEIF(($C$2:$C$101),C39,($F$2:$F$101)),F39) -> 214 | K39: Beauty | L39: 460
A40: PROD38 | B40: Sports Water Hydration Pack | C40: Sports | D40: Sims-Smith | E40: 135.61 | F40: 394 | G40: =IF(E40="",AVERAGEIF(($C$2:$C$101),C40,($E$2:$E$101)),E40) -> 135.61 | H40: =IF(F40="",AVERAGEIF(($C$2:$C$101),C40,($F$2:$F$101)),F40) -> 394 | K40: Clothing | L40: 496
...

Sheet Store_Dim
A1: Store_ID | B1: Store_Name | C1: Region | D1: City | E1: Store_Type
A2: STORE0 | B2: Rivera-Warner | C2: East | D2: Washingtonfurt | E2: Flagship
A3: STORE1 | B3: Martinez, Adkins and Johnson | C3: North | D3: Danielmouth | E3: Flagship
A4: STORE2 | B4: Black-Horn | C4: South | D4: North Nancyview | E4: Outlet
A5: STORE3 | B5: Johnson-Wright | C5: North | D5: Hoodberg | E5: Outlet
A6: STORE4 | B6: Alexander Group | C6: South | D6: Port Sharon | E6: Online
A7: STORE5 | B7: Gray Ltd | C7: North | D7: New Michaelchester | E7: Outlet
A8: STORE6 | B8: Benson-Elliott | C8: East | D8: Port Josephberg | E8: Online
A9: STORE7 | B9: Martinez-Mullins | C9: South | D9: Williamsfurt | E9: Online
A10: STORE8 | B10: Bean, Jones and Park | C10: West | D10: Thompsonborough | E10: Online
A11: STORE9 | B11: Moore, Padilla and Butler | C11: South | D11: East Johnstad | E11: Flagship
A12: STORE10 | B12: Hill, Wagner and Ballard | C12: East | D12: East Davidville | E12: Online
... A21: STORE19 | B21: Mann-Austin | C21: East | D21: Vasquezborough | E21: Online

Sheet Cleaned Store Dim
A1: Store_ID | B1: Store_Name | C1: Region | D1: City | E1: Store_Type | F1: New City (Replace) | H1: Region | I1: East | K1: Region | L1: North
A2: STORE0 | B2: Rivera-Warner | C2: East | D2: Washingtonfurt | E2: Flagship | F2: Washington
A3: STORE1 | B3: Martinez, Adkins and Johnson | C3: North | D3: Danielmouth | E3: Flagship | F3: Daniel | H3: Row Labels | I3: Count of Store_Name | K3: Row Labels | L3: Count of New City (Replace)
A4: STORE2 | B4: Black-Horn | C4: South | D4: North Nancyview | E4: Outlet | F4: North Nancy | H4: Flagship | I4: 3 | K4: Flagship | L4: 3
A5: STORE3 | B5: Johnson-Wright | C5: North | D5: Hoodberg | E5: Outlet | F5: Goldberg | H5: Online | I5: 3 | K5: Online | L5: 1
A6: STORE4 | B6: Alexander Group | C6: South | D6: Port Sharon | E6: Online | F6: Sharon | H6: Grand Total | I6: 6 | K6: Outlet | L6: 2
A7: STORE5 | B7: Gray Ltd | C7: North | D7: New Michaelchester | E7: Outlet | F7: Chester | K7: Grand Total | L7: 6
A8: STORE6 | B8: Benson-Elliott | C8: East | D8: Port Josephberg | E8: Online | F8: Joseph
A9: STORE7 | B9: Martinez-Mullins | C9: South | D9: Williamsfurt | E9: Online | F9: Williamsport
A10: STORE8 | B10: Bean, Jones and Park | C10: West | D10: Thompsonborough | E10: Online | F10: Thompson
A11: STORE9 | B11: Moore, Padilla and Butler | C11: South | D11: East Johnstad | E11: Flagship | F11: Johnstad | H11: Count of City | I11: Column Labels
A12: STORE10 | B12: Hill, Wagner and Ballard | C12: East | D12: East Davidville | E12: Online | F12: David | H12: Row Labels | I12: Flagship | J12: Grand Total
A13: STORE11 | B13: Aguirre-Keller | C13: South | D13: Lake Michael | E13: Online | F13: Lake | H13: East | I13: 3 | J13: 3
A14: STORE12 | B14: Thomas, Bridges and Harris | C14: North | D14: Sabrinatown | E14: Online | F14: Sabrina | H14: North | I14: 3 | J14: 3
A15: STORE13 | B15: Gardner, Humphrey and Contreras | C15: East | D15: Johnsonville | E15: Flagship | F15: Johnsonville | H15: South | I15: 1 | J15: 1
A16: STORE14 | B16: Mcdonald Inc | C16: South | D16: Christopherland | E16: Outlet | F16: Christopher | H16: West | I16: 1 | J16: 1
A17: STORE15 | B17: Shelton PLC | C17: North | D17: East Jenniferstad | E17: Flagship | F17: Jenniferstad | H17: Grand Total | I17: 8 | J17: 8
A18: STORE16 | B18: Frederick-Wright | C18: West | D18: New Jimmymouth | E18: Flagship | F18: New Jimmy
A19: STORE17 | B19: Holloway Ltd | C19: North | D19: Bensonhaven | E19: Flagship | F19: Benson
A20: STORE18 | B20: Guerrero-Schmitt | C20: East | D20: East Stevechester | E20: Flagship | F20: East Stevechester
A21: STORE19 | B21: Mann-Austin | C21: East | D21: Vasquezborough | E21: Online | F21: Vasquez
C22: =COUNTIF(C2:C21,"South") -> 6

Sheet Sales_Fact
A1: Sales_ID | B1: Order_Date | C1: Customer_ID | D1: Product_ID | E1: Store_ID | F1: Quantity | G1: Unit_Price | H1: Discount | I1: Payment_Type | J1: Total_Amount
A2: SALE0 | B2: 45480 | C2: CUST1409 | D2: PROD97 | E2: STORE3 | F2: 1 | G2: 218.04 | H2: 0.09 | I2: Credit Card | J2: 198.4164
A3: SALE1 | B3: 45285 | C3: CUST1467 | D3: PROD74 | E3: STORE17 | F3: 3 | G3: 104.47 | H3: 0.27 | I3: PayPal | J3: 228.7893
A4: SALE2 | B4: 45446 | C4: CUST1056 | D4: PROD49 | E4: STORE8 | F4: 4 | G4: 914.05 | H4: 0.25 | I4: Credit Card | J4: 2742.15
A5: SALE3 | B5: 45259 | C5: CUST1346 | D5: PROD76 | E5: STORE8 | F5: 1 | G5: 921.51 | H5: 0.16 | I5: COD | J5: 774.0684
A6: SALE4 | B6: 45297 | C6: CUST1493 | D6: PROD59 | E6: STORE5 | F6: 3 | G6: 745.3 | H6: 0.18 | I6: Credit Card | J6: 1833.438
A7: SALE5 | B7: 45499 | C7: CUST1116 | D7: PROD15 | E7: STORE7 | F7: 3 | G7: 147.01 | H7: 0.19 | I7: COD | J7: 357.2343
A8: SALE6 | B8: 45850 | C8: CUST1016 | D8: PROD56 | E8: STORE4 | F8: 2 | G8: 785.31 | H8: 0.15 | I8: PayPal | J8: 1335.027
A9: SALE7 | B9: 45248 | C9: CUST1152 | D9: PROD70 | E9: STORE8 | F9: 4 | G9: 342.39 | H9: 0.23 | I9: PayPal | J9: 1054.5612
A10: SALE8 | B10: 45781 | C10: CUST1187 | D10: PROD99 | E10: STORE5 | G10: 448.25 | H10: 0.07 | I10: PayPal | J10: 1250.6175
A11: SALE9 | B11: 45869 | C11: CUST1464 | D11: PROD33 | E11: STORE0 | F11: 2 | G11: 873.17 | H11: 0.23 | I11: PayPal | J11: 1344.6818
A12: SALE10 | B12: 45335 | C12: CUST1065 | D12: PROD24 | E12: STORE14 | F12: 1 | G12: 278.63 | H12: 0.07 | I12: Credit Card | J12: 259.1259
A13: SALE11 | B13: 45801 | C13: CUST1320 | D13: PROD39 | E13: STORE1 | F13: 4 | G13: 286.92 | H13: 0.17 | I13: Credit Card | J13: 952.5744
A14: SALE12 | B14: 45528 | C14: CUST1237 | D14: PROD88 | E14: STORE4 | F14: 4 | G14: 644.58 | H14: 0.01 | I14: Credit Card | J14: 2552.5368
A15: SALE13 | B15: 45875 | C15: CUST1443 | D15: PROD34 | E15: STORE16 | F15: 2 | G15: 316.9 | H15: 0.3 | I15: PayPal | J15: 443.66
A16: SALE14 | B16: 45829 | C16: CUST1348 | D16: PROD24 | E16: STORE15 | F16: 4 | G16: 403.47 | H16: 0.29 | I16: PayPal | J16: 1145.8548
A17: SALE15 | B17: 45636 | C17: CUST1435 | D17: PROD36 | E17: STORE9 | G17: 871.34 | H17: 0.04 | I17: COD | J17: 2509.4592
A18: SALE16 | B18: 45913 | C18: CUST1276 | D18: PROD65 | E18: STORE19 | F18: 2 | G18: 451.98 | H18: 0.25 | I18: Credit Card | J18: 677.97
A19: SALE17 | B19: 45637 | C19: CUST1079 | D19: PROD27 | E19: STORE4 | F19: 2 | G19: 502.69 | H19: 0.23 | I19: Credit Card | J19: 774.1426
A20: SALE18 | B20: 45517 | C20: CUST1094 | D20: PROD39 | E20: STORE4 | F20: 2 | G20: 559.23 | H20: 0.25 | I20: COD | J20: 838.845
A21: SALE19 | B21: 45369 | C21: CUST1239 | D21: PROD60 | E21: STORE13 | F21: 4 | H21: 0.04 | I21: COD | J21: 1782.4512
A22: SALE20 | B22: 45843 | C22: CUST1144 | D22: PROD72 | E22: STORE17 | F22: 3 | G22: 986.04 | H22: 0.27 | I22: COD | J22: 2159.4276
A23: SALE21 | B23: 45447 | C23: CUST1396 | D23: PROD43 | E23: STORE18 | F23: 1 | G23: 589.56 | H23: 0.22 | I23: Credit Card | J23: 459.8568
A24: SALE22 | B24: 45394 | C24: CUST1476 | D24: PROD69 | E24: STORE10 | F24: 3 | G24: 979.42 | H24: 0.03 | I24: PayPal | J24: 2850.1122
A25: SALE23 | B25: 45466 | C25: CUST1368 | D25: PROD12 | E25: STORE8 | F25: 1 | G25: 719.28 | H25: 0.08 | I25: Credit Card | J25: 661.7376
A26: SALE24 | B26: 45908 | C26: CUST1186 | D26: PROD67 | E26: STORE6 | F26: 3 | G26: 77.6 | H26: 0.07 | I26: Credit Card | J26: 216.504
A27: SALE25 | B27: 45552 | C27: CUST1381 | D27: PROD5 | E27: STORE3 | F27: 4 | G27: 852.71 | H27: 0.14 | I27: PayPal | J27: 2933.3224
A28: SALE26 | B28: 45294 | C28: CUST1213 | D28: PROD98 | E28: STORE8 | F28: 4 | G28: 156.16 | I28: Credit Card | J28: 599.6544
A29: SALE27 | B29: 45710 | C29: CUST1200 | D29: PROD77 | E29: STORE8 | F29: 3 | G29: 815.49 | H29: 0.17 | I29: Credit Card | J29: 2030.5701
A30: SALE28 | B30: 45923 | C30: CUST1148 | D30: PROD13 | E30: STORE2 | F30: 2 | G30: 74.21 | H30: 0.11 | I30: PayPal | J30: 132.0938
A31: SALE29 | B31: 45302 | C31: CUST1348 | D31: PROD99 | E31: STORE3 | G31: 451.67 | H31: 0.15 | I31: Credit Card | J31: 1535.678
A32: SALE30 | B32: 45217 | C32: CUST1028 | D32: PROD5 | E32: STORE19 | F32: 1 | G32: 429.38 | H32: 0.13 | I32: PayPal | J32: 373.5606
A33: SALE31 | B33: 45593 | C33: CUST1412 | D33: PROD53 | E33: STORE12 | F33: 2 | G33: 148.96 | H33: 0.03 | I33: COD | J33: 288.9824
A34: SALE32 | B34: 45597 | C34: CUST1398 | D34: PROD75 | E34: STORE8 | F34: 4 | G34: 313.83 | H34: 0.08 | I34: Credit Card | J34: 1154.8944
A35: SALE33 | B35: 45620 | C35: CUST1453 | D35: PROD12 | E35: STORE6 | F35: 2 | G35: 717.31 | H35: 0.15 | I35: Credit Card | J35: 1219.427
A36: SALE34 | B36: 45215 | C36: CUST1344 | D36: PROD79 | E36: STORE1 | G36: 873.22 | H36: 0.18 | I36: Credit Card | J36: 2148.1212
A37: SALE35 | B37: 45878 | C37: CUST1218 | D37: PROD16 | E37: STORE3 | F37: 4 | G37: 109.36 | H37: 0.19 | I37: COD | J37: 354.3264
A38: SALE36 | B38: 45635 | C38: CUST1086 | D38: PROD5 | E38: STORE7 | F38: 3 | G38: 559.52 | H38: 0.16 | I38: PayPal | J38: 1409.9904
A39: SALE37 | B39: 45329 | C39: CUST1492 | D39: PROD10 | E39: STORE17 | F39: 3 | G39: 121.76 | H39: 0.27 | I39: PayPal | J39: 266.6544
A40: SALE38 | B40: 45378 | C40: CUST1189 | D40: PROD33 | E40: STORE13 | F40: 4 | G40: 735.32 | H40: 0.06 | I40: COD | J40: 2764.8032
...

Sheet Cleaned Sales_Facts
A1: Sales_ID | B1: Order_Date (Delimited) | C1: Customer_ID | D1: Product_ID | E1: Store_ID | F1: Quantity | G1: Unit_Price | H1: Discount | I1: Payment_Type | J1: Total_Amount | K1: New Quantity | L1: New Unit Price | M1: New Discount | N1: New Total Amount | O1: Age | P1: Gender | Q1: New Loyalty | R1: Category | S1: Unit Cost | T1: Stock | U1: Region | V1: Store Type | W1: New City (Replace)
A2: SALE0 | B2: 45480 | C2: CUST1409 | D2: PROD97 | E2: STORE3 | F2: 1 | G2: 218.04 | H2: 0.09 | I2: Credit Card | J2: 198.4164 | K2: =IF(F2="",J2/(G2*(1-H2)),F2) -> 1 | L2: =IF(G2="",J2/(K2*(1-H2)),G2) -> 218.04 | M2: =IF(H2="",1-(J2/(K2*L2)),H2) -> 0.09 | N2: =IF(J2="",F2*G2*(1-H2),J2) -> 198.4164 | O2: =VLOOKUP(C2,'Cleaned Customer Dim'!$A$2:$D$501,4,FALSE) -> 55 | P2: =VLOOKUP(C2,'Cleaned Customer Dim'!$A$2:$E$501,5,FALSE) -> Male | Q2: =VLOOKUP(C2,'Cleaned Customer Dim'!$A$2:$J$501,10,FALSE) -> Gold | R2: =VLOOKUP(D2,'Cleaned Product Dim'!$A$2:$C$101,3,FALSE) -> Sports | S2: =VLOOKUP(D2,'Cleaned Product Dim'!$A$2:$G$101,7,FALSE) -> 245.98 | T2: =VLOOKUP(D2,'Cleaned Product Dim'!$A$2:$H$101,8,FALSE) -> 471 | U2: =VLOOKUP(E2,'Cleaned Store Dim'!$A$2:$C$21,3,FALSE) -> North | V2: =VLOOKUP(E2,'Cleaned Store Dim'!$A$2:$E$21,5,FALSE) -> Outlet | W2: =VLOOKUP(E2,'Cleaned Store Dim'!$A$2:$F$21,6,FALSE) -> Goldberg | Y2: New Quantity | AA2: New Unit Price | AC2: New Discount | AE2: New Total Amount
A3: SALE1 | B3: 45285 | C3: CUST1467 | D3: PROD74 | E3: STORE17 | F3: 3 | G3: 104.47 | H3: 0.27 | I3: PayPal | J3: 228.7893 | K3: =IF(F3="",J3/(G3*(1-H3)),F3) -> 3 | L3: =IF(G3="",J3/(K3*(1-H3)),G3) -> 104.47 | M3: =IF(H3="",1-(J3/(K3*L3)),H3) -> 0.27 | N3: =IF(J3="",F3*G3*(1-H3),J3) -> 228.7893 | O3: =VLOOKUP(C3,'Cleaned Customer Dim'!$A$2:$D$501,4,FALSE) -> 63 | P3: =VLOOKUP(C3,'Cleaned Customer Dim'!$A$2:$E$501,5,FALSE) -> Female | Q3: =VLOOKUP(C3,'Cleaned Customer Dim'!$A$2:$J$501,10,FALSE) -> Gold | R3: =VLOOKUP(D3,'Cleaned Product Dim'!$A$2:$C$101,3,FALSE) -> Electronics | S3: =VLOOKUP(D3,'Cleaned Product Dim'!$A$2:$G$101,7,FALSE) -> 403.71 | T3: =VLOOKUP(D3,'Cleaned Product Dim'!$A$2:$H$101,8,FALSE) -> 159 | U3: =VLOOKUP(E3,'Cleaned Store Dim'!$A$2:$C$21,3,FALSE) -> North | V3: =VLOOKUP(E3,'Cleaned Store Dim'!$A$2:$E$21,5,FALSE) -> Flagship | W3: =VLOOKUP(E3,'Cleaned Store Dim'!$A$2:$F$21,6,FALSE) -> Benson
A4: SALE2 | B4: 45357 | C4: CUST1056 | D4: PROD49 | E4: STORE8 | F4: 4 | G4: 914.05 | H4: 0.25 | I4: Credit Card | J4: 2742.15 | K4: =IF(F4="",J4/(G4*(1-H4)),F4) -> 4 | L4: =IF(G4="",J4/(K4*(1-H4)),G4) -> 914.05 | M4: =IF(H4="",1-(J4/(K4*L4)),H4) -> 0.25 | N4: =IF(J4="",F4*G4*(1-H4),J4) -> 2742.15 | O4: =VLOOKUP(C4,'Cleaned Customer Dim'!$A$2:$D$501,4,FALSE) -> 49 | P4: =VLOOKUP(C4,'Cleaned Customer Dim'!$A$2:$E$501,5,FALSE) -> Female | Q4: =VLOOKUP(C4,'Cleaned Customer Dim'!$A$2:$J$501,10,FALSE) -> Gold | R4: =VLOOKUP(D4,'Cleaned Product Dim'!$A$2:$C$101,3,FALSE) -> Beauty | S4: =VLOOKUP(D4,'Cleaned Product Dim'!$A$2:$G$101,7,FALSE) -> 43.29 | T4: =VLOOKUP(D4,'Cleaned Product Dim'!$A$2:$H$101,8,FALSE) -> 267 | U4: =VLOOKUP(E4,'Cleaned Store Dim'!$A$2:$C$21,3,FALSE) -> West | V4: =VLOOKUP(E4,'Cleaned Store Dim'!$A$2:$E$21,5,FALSE) -> Online | W4: =VLOOKUP(E4,'Cleaned Store Dim'!$A$2:$F$21,6,FALSE) -> Thompson | Y4: Mean | Z4: 2.482 | AA4: Mean | AB4: 513.58279 | AC4: Mean | AD4: 0.14796 | AE4: Mean | AF4: 1087.1973
A5: SALE3 | B5: 45259 | C5: CUST1346 | D5: PROD76 | E5: STORE8 | F5: 1 | G5: 921.51 | H5: 0.16 | I5: COD | J5: 774.0684 | K5: =IF(F5="",J5/(G5*(1-H5)),F5) -> 1 | L5: =IF(G5="",J5/(K5*(1-H5)),G5) -> 921.51 | M5: =IF(H5="",1-(J5/(K5*L5)),H5) -> 0.16 | N5: =IF(J5="",F5*G5*(1-H5),J5) -> 774.0684 | O5: =VLOOKUP(C5,'Cleaned Customer Dim'!$A$2:$D$501,4,FALSE) -> 58 | P5: =VLOOKUP(C5,'Cleaned Customer Dim'!$A$2:$E$501,5,FALSE) -> Female | Q5: =VLOOKUP(C5,'Cleaned Customer Dim'!$A$2:$J$501,10,FALSE) -> Platinum | R5: =VLOOKUP(D5,'Cleaned Product Dim'!$A$2:$C$101,3,FALSE) -> Electronics | S5: =VLOOKUP(D5,'Cleaned Product Dim'!$A$2:$G$101,7,FALSE) -> 392.89 | T5: =VLOOKUP(D5,'Cleaned Product Dim'!$A$2:$H$101,8,FALSE) -> 320 | U5: =VLOOKUP(E5,'Cleaned Store Dim'!$A$2:$C$21,3,FALSE) -> West | V5: =VLOOKUP(E5,'Cleaned Store Dim'!$A$2:$E$21,5,FALSE) -> Online | W5: =VLOOKUP(E5,'Cleaned Store Dim'!$A$2:$F$21,6,FALSE) -> Thompson | Y5: Standard Error | Z5: 0.024852501 | AA5: Standard Error | AB5: 6.3134988 | AC5: Standard Error | AD5: 0.0019598571 | AE5: Standard Error | AF5: 18.327237
A6: SALE4 | B6: 45444 | C6: CUST1493 | D6: PROD59 | E6: STORE5 | F6: 3 | G6: 745.3 | H6: 0.18 | I6: Credit Card | J6: 1833.438 | K6: =IF(F6="",J6/(G6*(1-H6)),F6) -> 3 | L6: =IF(G6="",J6/(K6*(1-H6)),G6) -> 745.3 | M6: =IF(H6="",1-(J6/(K6*L6)),H6) -> 0.18 | N6: =IF(J6="",F6*G6*(1-H6),J6) -> 1833.438 | O6: =VLOOKUP(C6,'Cleaned Customer Dim'!$A$2:$D$501,4,FALSE) -> 28 | P6: =VLOOKUP(C6,'Cleaned Customer Dim'!$A$2:$E$501,5,FALSE) -> Male | Q6: =VLOOKUP(C6,'Cleaned Customer Dim'!$A$2:$J$501,10,FALSE) -> Silver | R6: =VLOOKUP(D6,'Cleaned Product Dim'!$A$2:$C$101,3,FALSE) -> Beauty | S6: =VLOOKUP(D6,'Cleaned Product Dim'!$A$2:$G$101,7,FALSE) -> 17.31 | T6: =VLOOKUP(D6,'Cleaned Product Dim'!$A$2:$H$101,8,FALSE) -> 399 | U6: =VLOOKUP(E6,'Cleaned Store Dim'!$A$2:$C$21,3,FALSE) -> North | V6: =VLOOKUP(E6,'Cleaned Store Dim'!$A$2:$E$21,5,FALSE) -> Outlet | W6: =VLOOKUP(E6,'Cleaned Store Dim'!$A$2:$F$21,6,FALSE) -> Chester | Y6: Median | Z6: 2 | AA6: Median | AB6: 522.43 | AC6: Median | AD6: 0.14 | AE6: Median | AF6: 868.7182
A7: SALE5 | B7: 45499 | C7: CUST1116 | D7: PROD15 | E7: STORE7 | F7: 3 | G7: 147.01 | H7: 0.19 | I7: COD | J7: 357.2343 | K7: =IF(F7="",J7/(G7*(1-H7)),F7) -> 3 | L7: =IF(G7="",J7/(K7*(1-H7)),G7) -> 147.01 | M7: =IF(H7="",1-(J7/(K7*L7)),H7) -> 0.19 | N7: =IF(J7="",F7*G7*(1-H7),J7) -> 357.2343 | O7: =VLOOKUP(C7,'Cleaned Customer Dim'!$A$2:$D$501,4,FALSE) -> 18 | P7: =VLOOKUP(C7,'Cleaned Customer Dim'!$A$2:$E$501,5,FALSE) -> Female | Q7: =VLOOKUP(C7,'Cleaned Customer Dim'!$A$2:$J$501,10,FALSE) -> Platinum | R7: =VLOOKUP(D7,'Cleaned Product Dim'!$A$2:$C$101,3,FALSE) -> Electronics | S7: =VLOOKUP(D7,'Cleaned Product Dim'!$A$2:$G$101,7,FALSE) -> 465.34 | T7: =VLOOKUP(D7,'Cleaned Product Dim'!$A$2:$H$101,8,FALSE) -> 301 | U7: =VLOOKUP(E7,'Cleaned Store Dim'!$A$2:$C$21,3,FALSE) -> South | V7: =VLOOKUP(E7,'Cleaned Store Dim'!$A$2:$E$21,5,FALSE) -> Online | W7: =VLOOKUP(E7,'Cleaned Store Dim'!$A$2:$F$21,6,FALSE) -> Williamsport | Y7: Mode | Z7: 2 | AA7: Mode | AB7: 871.34 | AC7: Mode | AD7: 0.1 | AE7: Mode | AF7: #N/A
A8: SALE6 | B8: 45998 | C8: CUST1016 | D8: PROD56 | E8: STORE4 | F8: 2 | G8: 785.31 | H8: 0.15 | I8: PayPal | J8: 1335.027 | K8: =IF(F8="",J8/(G8*(1-H8)),F8) -> 2 | L8: =IF(G8="",J8/(K8*(1-H8)),G8) -> 785.31 | M8: =IF(H8="",1-(J8/(K8*L8)),H8) -> 0.15 | N8: =IF(J8="",F8*G8*(1-H8),J8) -> 1335.027 | O8: =VLOOKUP(C8,'Cleaned Customer Dim'!$A$2:$D$501,4,FALSE) -> 24 | P8: =VLOOKUP(C8,'Cleaned Customer Dim'!$A$2:$E$501,5,FALSE) -> Female | Q8: =VLOOKUP(C8,'Cleaned Customer Dim'!$A$2:$J$501,10,FALSE) -> Bronze | R8: =VLOOKUP(D8,'Cleaned Product Dim'!$A$2:$C$101,3,FALSE) -> Home | S8: =VLOOKUP(D8,'Cleaned Product Dim'!$A$2:$G$101,7,FALSE) -> 461.47 | T8: =VLOOKUP(D8,'Cleaned Product Dim'!$A$2:$H$101,8,FALSE) -> 190 | U8: =VLOOKUP(E8,'Cleaned Store Dim'!$A$2:$C$21,3,FALSE) -> South | V8: =VLOOKUP(E8,'Cleaned Store Dim'!$A$2:$E$21,5,FALSE) -> Online | W8: =VLOOKUP(E8,'Cleaned Store Dim'!$A$2:$F$21,6,FALSE) -> Sharon | Y8: Standard Deviation | Z8: 1.1114376 | AA8: Standard Deviation | AB8: 282.34825 | AC8: Standard Deviation | AD8: 0.087647473 | AE8: Standard Deviation | AF8: 819.61896
A9: SALE7 | B9: 45248 | C9: CUST1152 | D9: PROD70 | E9: STORE8 | F9: 4 | G9: 342.39 | H9: 0.23 | I9: PayPal | J9: 1054.5612 | K9: =IF(F9="",J9/(G9*(1-H9)),F9) -> 4 | L9: =IF(G9="",J9/(K9*(1-H9)),G9) -> 342.39 | M9: =IF(H9="",1-(J9/(K9*L9)),H9) -> 0.23 | N9: =IF(J9="",F9*G9*(1-H9),J9) -> 1054.5612 | O9: =VLOOKUP(C9,'Cleaned Customer Dim'!$A$2:$D$501,4,FALSE) -> 41 | P9: =VLOOKUP(C9,'Cleaned Customer Dim'!$A$2:$E$501,5,FALSE) -> Female | Q9: =VLOOKUP(C9,'Cleaned Customer Dim'!$A$2:$J$501,10,FALSE) -> Platinum | R9: =VLOOKUP(D9,'Cleaned Product Dim'!$A$2:$C$101,3,FALSE) -> Home | S9: =VLOOKUP(D9,'Cleaned Product Dim'!$A$2:$G$101,7,FALSE) -> 138.05 | T9: =VLOOKUP(D9,'Cleaned Product Dim'!$A$2:$H$101,8,FALSE) -> 89 | U9: =VLOOKUP(E9,'Cleaned Store Dim'!$A$2:$C$21,3,FALSE) -> West | V9: =VLOOKUP(E9,'Cleaned Store Dim'!$A$2:$E$21,5,FALSE) -> Online | W9: =VLOOKUP(E9,'Cleaned Store Dim'!$A$2:$F$21,6,FALSE) -> Thompson | Y9: Sample Variance | Z9: 1.2352936 | AA9: Sample Variance | AB9: 79720.534 | AC9: Sample Variance | AD9: 0.0076820794 | AE9: Sample Variance | AF9: 671775.25
A10: SALE8 | B10: 45752 | C10: CUST1187 | D10: PROD99 | E10: STORE5 | G10: 448.25 | H10: 0.07 | I10: PayPal | J10: 1250.6175 | K10: =IF(F10="",J10/(G10*(1-H10)),F10) -> 3 | L10: =IF(G10="",J10/(K10*(1-H10)),G10) -> 448.25 | M10: =IF(H10="",1-(J10/(K10*L10)),H10) -> 0.07 | N10: =IF(J10="",F10*G10*(1-H10),J10) -> 1250.6175 | O10: =VLOOKUP(C10,'Cleaned Customer Dim'!$A$2:$D$501,4,FALSE) -> 60 | P10: =VLOOKUP(C10,'Cleaned Customer Dim'!$A$2:$E$501,5,FALSE) -> Female | Q10: =VLOOKUP(C10,'Cleaned Customer Dim'!$A$2:$J$501,10,FALSE) -> Platinum | R10: =VLOOKUP(D10,'Cleaned Product Dim'!$A$2:$C$101,3,FALSE) -> Home | S10: =VLOOKUP(D10,'Cleaned Product Dim'!$A$2:$G$101,7,FALSE) -> 201.41 | T10: =VLOOKUP(D10,'Cleaned Product Dim'!$A$2:$H$101,8,FALSE) -> 146 | U10: =VLOOKUP(E10,'Cleaned Store Dim'!$A$2:$C$21,3,FALSE) -> North | V10: =VLOOKUP(E10,'Cleaned Store Dim'!$A$2:$E$21,5,FALSE) -> Outlet | W10: =VLOOKUP(E10,'Cleaned Store Dim'!$A$2:$F$21,6,FALSE) -> Chester | Y10: Kurtosis | Z10: -1.3441226 | AA10: Kurtosis | AB10: -1.1931883 | AC10: Kurtosis | AD10: -1.208024 | AE10: Kurtosis | AF10: 0.045826153
A11: SALE9 | B11: 45869 | C11: CUST1464 | D11: PROD33 | E11: STORE0 | F11: 2 | G11: 873.17 | H11: 0.23 | I11: PayPal | J11: 1344.6818 | K11: =IF(F11="",J11/(G11*(1-H11)),F11) -> 2 | L11: =IF(G11="",J11/(K11*(1-H11)),G11) -> 873.17 | M11: =IF(H11="",1-(J11/(K11*L11)),H11) -> 0.23 | N11: =IF(J11="",F11*G11*(1-H11),J11) -> 1344.6818 | O11: =VLOOKUP(C11,'Cleaned Customer Dim'!$A$2:$D$501,4,FALSE) -> 45 | P11: =VLOOKUP(C11,'Cleaned Customer Dim'!$A$2:$E$501,5,FALSE) -> Female | Q11: =VLOOKUP(C11,'Cleaned Customer Dim'!$A$2:$J$501,10,FALSE) -> Platinum | R11: =VLOOKUP(D11,'Cleaned Product Dim'!$A$2:$C$101,3,FALSE) -> Home | S11: =VLOOKUP(D11,'Cleaned Product Dim'!$A$2:$G$101,7,FALSE) -> 179.77 | T11: =VLOOKUP(D11,'Cleaned Product Dim'!$A$2:$H$101,8,FALSE) -> 305 | U11: =VLOOKUP(E11,'Cleaned Store Dim'!$A$2:$C$21,3,FALSE) -> East | V11: =VLOOKUP(E11,'Cleaned Store Dim'!$A$2:$E$21,5,FALSE) -> Flagship | W11: =VLOOKUP(E11,'Cleaned Store Dim'!$A$2:$F$21,6,FALSE) -> Washington | Y11: Skewness | Z11: 0.022378357 | AA11: Skewness | AB11: -0.034813907 | AC11: Skewness | AD11: 0.062951035 | AE11: Skewness | AF11: 0.87904704
A12: SALE10 | B12: 45335 | C12: CUST1065 | D12: PROD24 | E12: STORE14 | F12: 1 | G12: 278.63 | H12: 0.07 | I12: Credit Card | J12: 259.1259 | K12: =IF(F12="",J12/(G12*(1-H12)),F12) -> 1 | L12: =IF(G12="",J12/(K12*(1-H12)),G12) -> 278.63 | M12: =IF(H12="",1-(J12/(K12*L12)),H12) -> 0.07 | N12: =IF(J12="",F12*G12*(1-H12),J12) -> 259.1259 | O12: =VLOOKUP(C12,'Cleaned Customer Dim'!$A$2:$D$501,4,FALSE) -> 21 | P12: =VLOOKUP(C12,'Cleaned Customer Dim'!$A$2:$E$501,5,FALSE) -> Female | Q12: =VLOOKUP(C12,'Cleaned Customer Dim'!$A$2:$J$501,10,FALSE) -> Silver | R12: =VLOOKUP(D12,'Cleaned Product Dim'!$A$2:$C$101,3,FALSE) -> Sports | S12: =VLOOKUP(D12,'Cleaned Product Dim'!$A$2:$G$101,7,FALSE) -> 166.06 | T12: =VLOOKUP(D12,'Cleaned Product Dim'!$A$2:$H$101,8,FALSE) -> 340 | U12: =VLOOKUP(E12,'Cleaned Store Dim'!$A$2:$C$21,3,FALSE) -> South | V12: =VLOOKUP(E12,'Cleaned Store Dim'!$A$2:$E$21,5,FALSE) -> Outlet | W12: =VLOOKUP(E12,'Cleaned Store Dim'!$A$2:$F$21,6,FALSE) -> Christopher | Y12: Range | Z12: 3 | AA12: Range | AB12: 979.8 | AC12: Range | AD12: 0.3 | AE12: Range | AF12: 3889.7838
A13: SALE11 | B13: 45801 | C13: CUST1320 | D13: PROD39 | E13: STORE1 | F13: 4 | G13: 286.92 | H13: 0.17 | I13: Credit Card | J13: 952.5744 | K13: =IF(F13="",J13/(G13*(1-H13)),F13) -> 4 | L13: =IF(G13="",J13/(K13*(1-H13)),G13) -> 286.92 | M13: =IF(H13="",1-(J13/(K13*L13)),H13) -> 0.17 | N13: =IF(J13="",F13*G13*(1-H13),J13) -> 952.5744 | O13: =VLOOKUP(C13,'Cleaned Customer Dim'!$A$2:$D$501,4,FALSE) -> 34 | P13: =VLOOKUP(C13,'Cleaned Customer Dim'!$A$2:$E$501,5,FALSE) -> Female | Q13: =VLOOKUP(C13,'Cleaned Customer Dim'!$A$2:$J$501,10,FALSE) -> Bronze | R13: =VLOOKUP(D13,'Cleaned Product Dim'!$A$2:$C$101,3,FALSE) -> Electronics | S13: =VLOOKUP(D13,'Cleaned Product Dim'!$A$2:$G$101,7,FALSE) -> 326.06 | T13: =VLOOKUP(D13,'Cleaned Product Dim'!$A$2:$H$101,8,FALSE) -> 301 | U13: =VLOOKUP(E13,'Cleaned Store Dim'!$A$2:$C$21,3,FALSE) -> North | V13: =VLOOKUP(E13,'Cleaned Store Dim'!$A$2:$E$21,5,FALSE) -> Flagship | W13: =VLOOKUP(E13,'Cleaned Store Dim'!$A$2:$F$21,6,FALSE) -> Daniel | Y13: Minimum | Z13: 1 | AA13: Minimum | AB13: 20.09 | AC13: Minimum | AD13: 0 | AE13: Minimum | AF13: 18.459
A14: SALE12 | B14: 45528 | C14: CUST1237 | D14: PROD88 | E14: STORE4 | F14: 4 | G14: 644.58 | H14: 0.01 | I14: Credit Card | J14: 2552.5368 | K14: =IF(F14="",J14/(G14*(1-H14)),F14) -> 4 | L14: =IF(G14="",J14/(K14*(1-H14)),G14) -> 644.58 | M14: =IF(H14="",1-(J14/(K14*L14)),H14) -> 0.01 | N14: =IF(J14="",F14*G14*(1-H14),J14) -> 2552.5368 | O14: =VLOOKUP(C14,'Cleaned Customer Dim'!$A$2:$D$501,4,FALSE) -> 41 | P14: =VLOOKUP(C14,'Cleaned Customer Dim'!$A$2:$E$501,5,FALSE) -> Female | Q14: =VLOOKUP(C14,'Cleaned Customer Dim'!$A$2:$J$501,10,FALSE) -> Gold | R14: =VLOOKUP(D14,'Cleaned Product Dim'!$A$2:$C$101,3,FALSE) -> Sports | S14: =VLOOKUP(D14,'Cleaned Product Dim'!$A$2:$G$101,7,FALSE) -> 131.24 | T14: =VLOOKUP(D14,'Cleaned Product Dim'!$A$2:$H$101,8,FALSE) -> 232 | U14: =VLOOKUP(E14,'Cleaned Store Dim'!$A$2:$C$21,3,FALSE) -> South | V14: =VLOOKUP(E14,'Cleaned Store Dim'!$A$2:$E$21,5,FALSE) -> Online | W14: =VLOOKUP(E14,'Cleaned Store Dim'!$A$2:$F$21,6,FALSE) -> Sharon | Y14: Maximum | Z14: 4 | AA14: Maximum | AB14: 999.89 | AC14: Maximum | AD14: 0.3 | AE14: Maximum | AF14: 3908.2428
A15: SALE13 | B15: 45816 | C15: CUST1443 | D15: PROD34 | E15: STORE16 | F15: 2 | G15: 316.9 | H15: 0.3 | I15: PayPal | J15: 443.66 | K15: =IF(F15="",J15/(G15*(1-H15)),F15) -> 2 | L15: =IF(G15="",J15/(K15*(1-H15)),G15) -> 316.9 | M15: =IF(H15="",1-(J15/(K15*L15)),H15) -> 0.3 | N15: =IF(J15="",F15*G15*(1-H15),J15) -> 443.66 | O15: =VLOOKUP(C15,'Cleaned Customer Dim'!$A$2:$D$501,4,FALSE) -> 51 | P15: =VLOOKUP(C15,'Cleaned Customer Dim'!$A$2:$E$501,5,FALSE) -> Male | Q15: =VLOOKUP(C15,'Cleaned Customer Dim'!$A$2:$J$501,10,FALSE) -> Silver | R15: =VLOOKUP(D15,'Cleaned Product Dim'!$A$2:$C$101,3,FALSE) -> Electronics | S15: =VLOOKUP(D15,'Cleaned Product Dim'!$A$2:$G$101,7,FALSE) -> 419.28 | T15: =VLOOKUP(D15,'Cleaned Product Dim'!$A$2:$H$101,8,FALSE) -> 86 | U15: =VLOOKUP(E15,'Cleaned Store Dim'!$A$2:$C$21,3,FALSE) -> West | V15: =VLOOKUP(E15,'Cleaned Store Dim'!$A$2:$E$21,5,FALSE) -> Flagship | W15: =VLOOKUP(E15,'Cleaned Store Dim'!$A$2:$F$21,6,FALSE) -> New Jimmy | Y15: Sum | Z15: 4964 | AA15: Sum | AB15: 1027165.6 | AC15: Sum | AD15: 295.92 | AE15: Sum | AF15: 2174394.7
A16: SALE14 | B16: 45829 | C16: CUST1348 | D16: PROD24 | E16: STORE15 | F16: 4 | G16: 403.47 | H16: 0.29 | I16: PayPal | J16: 1145.8548 | K16: =IF(F16="",J16/(G16*(1-H16)),F16) -> 4 | L16: =IF(G16="",J16/(K16*(1-H16)),G16) -> 403.47 | M16: =IF(H16="",1-(J16/(K16*L16)),H16) -> 0.29 | N16: =IF(J16="",F16*G16*(1-H16),J16) -> 1145.8548 | O16: =VLOOKUP(C16,'Cleaned Customer Dim'!$A$2:$D$501,4,FALSE) -> 55 | P16: =VLOOKUP(C16,'Cleaned Customer Dim'!$A$2:$E$501,5,FALSE) -> Male | Q16: =VLOOKUP(C16,'Cleaned Customer Dim'!$A$2:$J$501,10,FALSE) -> Silver | R16: =VLOOKUP(D16,'Cleaned Product Dim'!$A$2:$C$101,3,FALSE) -> Sports | S16: =VLOOKUP(D16,'Cleaned Product Dim'!$A$2:$G$101,7,FALSE) -> 166.06 | T16: =VLOOKUP(D16,'Cleaned Product Dim'!$A$2:$H$101,8,FALSE) -> 340 | U16: =VLOOKUP(E16,'Cleaned Store Dim'!$A$2:$C$21,3,FALSE) -> North | V16: =VLOOKUP(E16,'Cleaned Store Dim'!$A$2:$E$21,5,FALSE) -> Flagship | W16: =VLOOKUP(E16,'Cleaned Store Dim'!$A$2:$F$21,6,FALSE) -> Jenniferstad | Y16: Count | Z16: 2000 | AA16: Count | AB16: 2000 | AC16: Count | AD16: 2000 | AE16: Count | AF16: 2000
A17: SALE15 | B17: 45577 | C17: CUST1435 | D17: PROD36 | E17: STORE9 | G17: 871.34 | H17: 0.04 | I17: COD | J17: 2509.4592 | K17: =IF(F17="",J17/(G17*(1-H17)),F17) -> 3 | L17: =IF(G17="",J17/(K17*(1-H17)),G17) -> 871.34 | M17: =IF(H17="",1-(J17/(K17*L17)),H17) -> 0.04 | N17: =IF(J17="",F17*G17*(1-H17),J17) -> 2509.4592 | O17: =VLOOKUP(C17,'Cleaned Customer Dim'!$A$2:$D$501,4,FALSE) -> 37 | P17: =VLOOKUP(C17,'Cleaned Customer Dim'!$A$2:$E$501,5,FALSE) -> Female | Q17: =VLOOKUP(C17,'Cleaned Customer Dim'!$A$2:$J$501,10,FALSE) -> Silver | R17: =VLOOKUP(D17,'Cleaned Product Dim'!$A$2:$C$101,3,FALSE) -> Clothing | S17: =VLOOKUP(D17,'Cleaned Product Dim'!$A$2:$G$101,7,FALSE) -> 223.43 | T17: =VLOOKUP(D17,'Cleaned Product Dim'!$A$2:$H$101,8,FALSE) -> 154 | U17: =VLOOKUP(E17,'Cleaned Store Dim'!$A$2:$C$21,3,FALSE) -> South | V17: =VLOOKUP(E17,'Cleaned Store Dim'!$A$2:$E$21,5,FALSE) -> Flagship | W17: =VLOOKUP(E17,'Cleaned Store Dim'!$A$2:$F$21,6,FALSE) -> Johnstad
A18: SALE16 | B18: 45913 | C18: CUST1276 | D18: PROD65 | E18: STORE19 | F18: 2 | G18: 451.98 | H18: 0.25 | I18: Credit Card | J18: 677.97 | K18: =IF(F18="",J18/(G18*(1-H18)),F18) -> 2 | L18: =IF(G18="",J18/(K18*(1-H18)),G18) -> 451.98 | M18: =IF(H18="",1-(J18/(K18*L18)),H18) -> 0.25 | N18: =IF(J18="",F18*G18*(1-H18),J18) -> 677.97 | O18: =VLOOKUP(C18,'Cleaned Customer Dim'!$A$2:$D$501,4,FALSE) -> 38 | P18: =VLOOKUP(C18,'Cleaned Customer Dim'!$A$2:$E$501,5,FALSE) -> Male | Q18: =VLOOKUP(C18,'Cleaned Customer Dim'!$A$2:$J$501,10,FALSE) -> Gold | R18: =VLOOKUP(D18,'Cleaned Product Dim'!$A$2:$C$101,3,FALSE) -> Sports | S18: =VLOOKUP(D18,'Cleaned Product Dim'!$A$2:$G$101,7,FALSE) -> 240.63 | T18: =VLOOKUP(D18,'Cleaned Product Dim'!$A$2:$H$101,8,FALSE) -> 423 | U18: =VLOOKUP(E18,'Cleaned Store Dim'!$A$2:$C$21,3,FALSE) -> East | V18: =VLOOKUP(E18,'Cleaned Store Dim'!$A$2:$E$21,5,FALSE) -> Online | W18: =VLOOKUP(E18,'Cleaned Store Dim'!$A$2:$F$21,6,FALSE) -> Vasquez
A19: SALE17 | B19: 45608 | C19: CUST1079 | D19: PROD27 | E19: STORE4 | F19: 2 | G19: 502.69 | H19: 0.23 | I19: Credit Card | J19: 774.1426 | K19: =IF(F19="",J19/(G19*(1-H19)),F19) -> 2 | L19: =IF(G19="",J19/(K19*(1-H19)),G19) -> 502.69 | M19: =IF(H19="",1-(J19/(K19*L19)),H19) -> 0.23 | N19: =IF(J19="",F19*G19*(1-H19),J19) -> 774.1426 | O19: =VLOOKUP(C19,'Cleaned Customer Dim'!$A$2:$D$501,4,FALSE) -> 22 | P19: =VLOOKUP(C19,'Cleaned Customer Dim'!$A$2:$E$501,5,FALSE) -> Female | Q19: =VLOOKUP(C19,'Cleaned Customer Dim'!$A$2:$J$501,10,FALSE) -> Platinum | R19: =VLOOKUP(D19,'Cleaned Product Dim'!$A$2:$C$101,3,FALSE) -> Home | S19: =VLOOKUP(D19,'Cleaned Product Dim'!$A$2:$G$101,7,FALSE) -> 234.806 | T19: =VLOOKUP(D19,'Cleaned Product Dim'!$A$2:$H$101,8,FALSE) -> 378 | U19: =VLOOKUP(E19,'Cleaned Store Dim'!$A$2:$C$21,3,FALSE) -> South | V19: =VLOOKUP(E19,'Cleaned Store Dim'!$A$2:$E$21,5,FALSE) -> Online | W19: =VLOOKUP(E19,'Cleaned Store Dim'!$A$2:$F$21,6,FALSE) -> Sharon
A20: SALE18 | B20: 45517 | C20: CUST1094 | D20: PROD39 | E20: STORE4 | F20: 2 | G20: 559.23 | H20: 0.25 | I20: COD | J20: 838.845 | K20: =IF(F20="",J20/(G20*(1-H20)),F20) -> 2 | L20: =IF(G20="",J20/(K20*(1-H20)),G20) -> 559.23 | M20: =IF(H20="",1-(J20/(K20*L20)),H20) -> 0.25 | N20: =IF(J20="",F20*G20*(1-H20),J20) -> 838.845 | O20: =VLOOKUP(C20,'Cleaned Customer Dim'!$A$2:$D$501,4,FALSE) -> 43 | P20: =VLOOKUP(C20,'Cleaned Customer Dim'!$A$2:$E$501,5,FALSE) -> Female | Q20: =VLOOKUP(C20,'Cleaned Customer Dim'!$A$2:$J$501,10,FALSE) -> Gold | R20: =VLOOKUP(D20,'Cleaned Product Dim'!$A$2:$C$101,3,FALSE) -> Electronics | S20: =VLOOKUP(D20,'Cleaned Product Dim'!$A$2:$G$101,7,FALSE) -> 326.06 | T20: =VLOOKUP(D20,'Cleaned Product Dim'!$A$2:$H$101,8,FALSE) -> 301 | U20: =VLOOKUP(E20,'Cleaned Store Dim'!$A$2:$C$21,3,FALSE) -> South | V20: =VLOOKUP(E20,'Cleaned Store Dim'!$A$2:$E$21,5,FALSE) -> Online | W20: =VLOOKUP(E20,'Cleaned Store Dim'!$A$2:$F$21,6,FALSE) -> Sharon
